<mujoco model="turtle_body">
    <compiler angle="radian" meshdir="meshes/" autolimits="true" />
    <option integrator="implicit" timestep="0.005" gravity="0 0 0" density="1000" viscosity="0.0009" cone="elliptic" />
    <asset>
        <mesh name="fr13-h105k" file="fr13-h105k.stl"/>
        <mesh name="fr13-s105k" file="fr13-s105k.stl"/>
        <mesh name="wte3-m-locking-flange-seal-r1-rp" file="wte3-m-locking-flange-seal-r1-rp.stl"/>
        <mesh name="xw540.n105.i101.stp" file="xw540.n105.i101.stp.stl"/>
        <mesh name="tube" file="tube.stl"/>
        <mesh name="shoulder_adapter" file="shoulder_adapter.stl"/>
        <mesh name="enclosure_plate" file="enclosure_plate.stl"/>
        <mesh name="head_bottom" file="head_bottom.stl"/>
        <mesh name="head_top" file="head_top.stl"/>
        <mesh name="explorehd_2.0_public.step-1-solid1" file="explorehd_2.0_public.step-1-solid1.stl"/>
        <mesh name="explorehd_2.0_case_public.step-1_standoff_and_washer_v4_(1).step-1-solid1"
              file="explorehd_2.0_case_public.step-1_standoff_and_washer_v4_(1).step-1-solid1.stl"/>
        <mesh name="fr13-s106k" file="fr13-s106k.stl"/>
        <mesh name="front_flipper" file="front_flipper.stl"/>
        <mesh name="front_flipper_straight" file="front_flipper_straight.stl"/>
        <mesh name="rigid_flipper_1" file="rigid_flipper_1.stl"/>
        <mesh name="rigid_flipper_2" file="rigid_flipper_2.stl"/>
        <mesh name="rigid_flipper_4" file="rigid_flipper_4.stl"/>
        <mesh name="rigid_flipper_3" file="rigid_flipper_3.stl"/>
        <mesh name="rear_flipper" file="rear_flipper.stl"/>
    </asset>
    <default>
        <default class="fluid-ellipsoid-model">
            <geom fluidshape="ellipsoid"/>
        </default>
    </default>
    <worldbody>
        <!-- coordinate system: x: left, y: back, z: up-->
        <body name="base" quat="0.0 0.0 0.0 1.0">
            <!-- coordinate system: x: right, y: forward, z: up-->
            <inertial pos="4.14357e-07 0.0844756 0.00697314" quat="0.500725 0.499269 -0.499294 0.500709" mass="2.9553"
                      diaginertia="0.0661585 0.0610428 0.0094174"/>
            <joint name="world_frame_to_base" type="free" axis="0.0 -1.0 0.0" />
            <site name="base_cog" pos="4.14357e-07 0.0844756 0.00697314"/>
            <geom pos="0.0698948 0.294805 -0.0103195" quat="0.5 0.5 -0.5 0.5" type="mesh" contype="0" conaffinity="0"
                  group="1" density="0" rgba="0.796078 0.823529 0.937255 1" mesh="fr13-h105k"/>
            <geom pos="0.0698948 0.294805 -0.0103195" quat="0.5 0.5 -0.5 0.5" type="mesh"
                  rgba="0.796078 0.823529 0.937255 1" mesh="fr13-h105k"/>
            <geom pos="0.0678948 -0.0134434 -0.0103195" quat="0.5 0.5 0.5 -0.5" type="mesh" contype="0" conaffinity="0"
                  group="1" density="0" rgba="0.796078 0.823529 0.937255 1" mesh="fr13-s105k"/>
            <geom pos="0.0678948 -0.0134434 -0.0103195" quat="0.5 0.5 0.5 -0.5" type="mesh"
                  rgba="0.796078 0.823529 0.937255 1" mesh="fr13-s105k"/>
            <geom pos="0 0.0172412 0.010315" quat="0.707107 0.707107 0 0" type="mesh" contype="0" conaffinity="0"
                  group="1" density="0" rgba="0.768627 0.886275 0.952941 1" mesh="wte3-m-locking-flange-seal-r1-rp"/>
            <geom pos="0 0.0172412 0.010315" quat="0.707107 0.707107 0 0" type="mesh"
                  rgba="0.768627 0.886275 0.952941 1" mesh="wte3-m-locking-flange-seal-r1-rp"/>
            <geom pos="0.118895 -0.0134434 -0.0103195" quat="0.5 0.5 0.5 -0.5" type="mesh" contype="0" conaffinity="0"
                  group="1" density="0" rgba="0.615686 0.811765 0.929412 1" mesh="xw540.n105.i101.stp"/>
            <geom pos="0.118895 -0.0134434 -0.0103195" quat="0.5 0.5 0.5 -0.5" type="mesh"
                  rgba="0.615686 0.811765 0.929412 1" mesh="xw540.n105.i101.stp"/>
            <geom pos="-0.118895 -0.0135704 -0.0103195" quat="0.5 0.5 -0.5 0.5" type="mesh" contype="0" conaffinity="0"
                  group="1" density="0" rgba="0.615686 0.811765 0.929412 1" mesh="xw540.n105.i101.stp"/>
            <geom pos="-0.118895 -0.0135704 -0.0103195" quat="0.5 0.5 -0.5 0.5" type="mesh"
                  rgba="0.615686 0.811765 0.929412 1" mesh="xw540.n105.i101.stp"/>
            <geom pos="0 0.140241 0.010315" quat="0.707107 0.707107 0 0" type="mesh" class="fluid-ellipsoid-model"
                  contype="0" conaffinity="0" group="1" density="0" rgba="1 1 1 1" mesh="tube"/>
            <geom pos="0 0.140241 0.010315" quat="0.707107 0.707107 0 0" type="mesh" rgba="1 1 1 1" mesh="tube"/>
            <geom pos="-0.0698948 0.294678 -0.0103195" quat="0.5 -0.5 -0.5 -0.5" type="mesh" contype="0" conaffinity="0"
                  group="1" density="0" rgba="0.796078 0.823529 0.937255 1" mesh="fr13-h105k"/>
            <geom pos="-0.0698948 0.294678 -0.0103195" quat="0.5 -0.5 -0.5 -0.5" type="mesh"
                  rgba="0.796078 0.823529 0.937255 1" mesh="fr13-h105k"/>
            <geom pos="0 0.263241 0.010315" quat="0 0 -0.707107 -0.707107" type="mesh" contype="0" conaffinity="0"
                  group="1" density="0" rgba="0.768627 0.886275 0.952941 1" mesh="wte3-m-locking-flange-seal-r1-rp"/>
            <geom pos="0 0.263241 0.010315" quat="0 0 -0.707107 -0.707107" type="mesh"
                  rgba="0.768627 0.886275 0.952941 1" mesh="wte3-m-locking-flange-seal-r1-rp"/>
            <geom pos="-0.0678948 -0.0135704 -0.0103195" quat="0.5 0.5 -0.5 0.5" type="mesh" contype="0" conaffinity="0"
                  group="1" density="0" rgba="0.796078 0.823529 0.937255 1" mesh="fr13-s105k"/>
            <geom pos="-0.0678948 -0.0135704 -0.0103195" quat="0.5 0.5 -0.5 0.5" type="mesh"
                  rgba="0.796078 0.823529 0.937255 1" mesh="fr13-s105k"/>
            <geom pos="-0.0479333 -0.00907036 -0.0384564" quat="0.707107 0.707107 0 0" type="mesh" contype="0"
                  conaffinity="0" group="1" density="0" rgba="0.25098 0.25098 0.25098 1" mesh="shoulder_adapter"/>
            <geom pos="-0.0479333 -0.00907036 -0.0384564" quat="0.707107 0.707107 0 0" type="mesh"
                  rgba="0.25098 0.25098 0.25098 1" mesh="shoulder_adapter"/>
            <geom pos="-0.0479333 -0.00900686 -0.0384564" quat="0.707107 0.707107 0 0" type="mesh" contype="0"
                  conaffinity="0" group="1" density="0" rgba="0.109804 0.109804 0.109804 1" mesh="shoulder_adapter"/>
            <geom pos="-0.0479333 -0.00900686 -0.0384564" quat="0.707107 0.707107 0 0" type="mesh"
                  rgba="0.109804 0.109804 0.109804 1" mesh="shoulder_adapter"/>
            <geom pos="-0.0479333 -0.00900686 -0.0384564" quat="0.707107 0.707107 0 0" type="mesh" contype="0"
                  conaffinity="0" group="1" density="0" rgba="1 1 1 1" mesh="enclosure_plate"/>
            <geom pos="-0.0479333 -0.00900686 -0.0384564" quat="0.707107 0.707107 0 0" type="mesh" rgba="1 1 1 1"
                  mesh="enclosure_plate"/>
            <geom pos="0 -0.0406034 0.010315" quat="0.707107 0.707107 0 0" type="mesh" class="fluid-ellipsoid-model"
                  contype="0" conaffinity="0" group="1" density="0" rgba="0.796078 0.823529 0.937255 1" mesh="head_bottom"/>
            <geom pos="0 -0.0406034 0.010315" quat="0.707107 0.707107 0 0" type="mesh"
                  rgba="0.796078 0.823529 0.937255 1" mesh="head_bottom"/>
            <geom pos="0 -0.0406034 0.010315" quat="0.707107 0.707107 0 0" type="mesh" class="fluid-ellipsoid-model"
                  contype="0" conaffinity="0" group="1" density="0" rgba="0.796078 0.823529 0.937255 1" mesh="head_top"/>
            <geom pos="0 -0.0406034 0.010315" quat="0.707107 0.707107 0 0" type="mesh"
                  rgba="0.796078 0.823529 0.937255 1" mesh="head_top"/>
            <geom pos="-0.0479333 0.299178 -0.0384564" quat="0.707107 0.707107 0 0" type="mesh" contype="0"
                  conaffinity="0" group="1" density="0" rgba="0.25098 0.25098 0.25098 1" mesh="shoulder_adapter"/>
            <geom pos="-0.0479333 0.299178 -0.0384564" quat="0.707107 0.707107 0 0" type="mesh"
                  rgba="0.25098 0.25098 0.25098 1" mesh="shoulder_adapter"/>
            <geom pos="-0.0479333 0.299241 -0.0384564" quat="0.707107 0.707107 0 0" type="mesh" contype="0"
                  conaffinity="0" group="1" density="0" rgba="0.109804 0.109804 0.109804 1" mesh="shoulder_adapter"/>
            <geom pos="-0.0479333 0.299241 -0.0384564" quat="0.707107 0.707107 0 0" type="mesh"
                  rgba="0.109804 0.109804 0.109804 1" mesh="shoulder_adapter"/>
            <geom pos="-0.0479333 0.299241 -0.0384564" quat="0.707107 0.707107 0 0" type="mesh" class="fluid-ellipsoid-model"
                  contype="0" conaffinity="0" group="1" density="0" rgba="1 1 1 1" mesh="enclosure_plate"/>
            <geom pos="-0.0479333 0.299241 -0.0384564" quat="0.707107 0.707107 0 0" type="mesh" rgba="1 1 1 1"
                  mesh="enclosure_plate"/>
            <geom pos="-0.0267103 -0.14548 0.035703" quat="0.560986 0.430459 -0.560986 0.430459" type="mesh" contype="0"
                  conaffinity="0" group="1" density="0" rgba="0.796078 0.823529 0.937255 1"
                  mesh="explorehd_2.0_public.step-1-solid1"/>
            <geom pos="-0.0267103 -0.14548 0.035703" quat="0.560986 0.430459 -0.560986 0.430459" type="mesh"
                  rgba="0.796078 0.823529 0.937255 1" mesh="explorehd_2.0_public.step-1-solid1"/>
            <geom pos="-0.0267103 -0.14548 0.035703" quat="0.560986 0.430459 -0.560986 0.430459" type="mesh" contype="0"
                  conaffinity="0" group="1" density="0" rgba="0.796078 0.823529 0.937255 1"
                  mesh="explorehd_2.0_case_public.step-1_standoff_and_washer_v4_(1).step-1-solid1"/>
            <geom pos="-0.0267103 -0.14548 0.035703" quat="0.560986 0.430459 -0.560986 0.430459" type="mesh"
                  rgba="0.796078 0.823529 0.937255 1"
                  mesh="explorehd_2.0_case_public.step-1_standoff_and_washer_v4_(1).step-1-solid1"/>
            <geom pos="0.0209147 -0.147033 0.035703" quat="0.430459 0.560986 -0.430459 0.560986" type="mesh" contype="0"
                  conaffinity="0" group="1" density="0" rgba="0.796078 0.823529 0.937255 1"
                  mesh="explorehd_2.0_public.step-1-solid1"/>
            <geom pos="0.0209147 -0.147033 0.035703" quat="0.430459 0.560986 -0.430459 0.560986" type="mesh"
                  rgba="0.796078 0.823529 0.937255 1" mesh="explorehd_2.0_public.step-1-solid1"/>
            <geom pos="0.0209147 -0.147033 0.035703" quat="0.430459 0.560986 -0.430459 0.560986" type="mesh" contype="0"
                  conaffinity="0" group="1" density="0" rgba="0.796078 0.823529 0.937255 1"
                  mesh="explorehd_2.0_case_public.step-1_standoff_and_washer_v4_(1).step-1-solid1"/>
            <geom pos="0.0209147 -0.147033 0.035703" quat="0.430459 0.560986 -0.430459 0.560986" type="mesh"
                  rgba="0.796078 0.823529 0.937255 1"
                  mesh="explorehd_2.0_case_public.step-1_standoff_and_washer_v4_(1).step-1-solid1"/>
            <site name="arm_right_base" pos="0.0 -0.0150704 0.0" />
            <body name="front_right_link_1" pos="-0.118895 -0.0400704 -0.0103195" quat="0 0 -0.707107 -0.707107">
                <inertial pos="0.053506 -0.00012799 0.0413092" quat="0.701572 0.0987989 0.0897983 0.69998"
                          mass="0.237653" diaginertia="0.000125729 0.00012228 8.62056e-05"/>
                <joint name="shoulder_right_1" pos="0 0 0" axis="0 0 1"/>
                <geom pos="0.032 0 0.042" quat="0.5 0.5 0.5 -0.5" type="mesh" contype="0" conaffinity="0" group="1"
                      density="0" rgba="0.796078 0.823529 0.937255 1" mesh="fr13-s106k"/>
                <geom pos="0.032 0 0.042" quat="0.5 0.5 0.5 -0.5" type="mesh" rgba="0.796078 0.823529 0.937255 1"
                      mesh="fr13-s106k"/>
                <geom pos="0.03 0 0.0265" quat="0.5 -0.5 -0.5 -0.5" type="mesh" contype="0" conaffinity="0" group="1"
                      density="0" rgba="0.796078 0.823529 0.937255 1" mesh="fr13-h105k"/>
                <!--<geom pos="0.03 0 0.0265" quat="0.5 -0.5 -0.5 -0.5" type="mesh" rgba="0.796078 0.823529 0.937255 1"
                      mesh="fr13-h105k"/>-->
                <geom pos="0.058 0 0.0575" quat="0.707107 0.707107 0 0" type="mesh" contype="0" conaffinity="0"
                      group="1" density="0" rgba="0.615686 0.811765 0.929412 1" mesh="xw540.n105.i101.stp"/>
                <geom pos="0.058 0 0.0575" quat="0.707107 0.707107 0 0" type="mesh" rgba="0.615686 0.811765 0.929412 1"
                      mesh="xw540.n105.i101.stp"/>
                <body name="front_right_link_2" pos="0.058 -0.0265 0.0575" quat="0.5 -0.5 0.5 0.5">
                    <inertial pos="-0.0161017 -0.000139957 -0.0242536" quat="-0.00747436 0.704985 0.00455773 0.709168"
                              mass="0.217333" diaginertia="0.000103428 9.13442e-05 6.49096e-05"/>
                    <joint name="shoulder_right_2" pos="0 0 0" axis="0 0 1"/>
                    <geom pos="-0.0155 0 0" quat="0.707107 -0.707107 0 0" type="mesh" contype="0" conaffinity="0"
                          group="1" density="0" rgba="0.796078 0.823529 0.937255 1" mesh="fr13-s106k"/>
                    <geom pos="-0.0155 0 0" quat="0.707107 -0.707107 0 0" type="mesh"
                          rgba="0.796078 0.823529 0.937255 1" mesh="fr13-s106k"/>
                    <geom pos="-0.031 0 -0.026" quat="0.5 0.5 -0.5 0.5" type="mesh" contype="0" conaffinity="0"
                          group="1" density="0" rgba="0.615686 0.811765 0.929412 1" mesh="xw540.n105.i101.stp"/>
                    <geom pos="-0.031 0 -0.026" quat="0.5 0.5 -0.5 0.5" type="mesh" rgba="0.615686 0.811765 0.929412 1"
                          mesh="xw540.n105.i101.stp"/>
                    <!-- <body name="front_flipper_right" pos="-0.031 -0.0265 -0.026" quat="0.707107 -0.707107 0 0">
                        <inertial pos="-0.00442517 9.82085e-05 -0.127518" quat="0.706603 0.0265123 0.026473 0.706618" mass="0.45" diaginertia="0.00191412 0.00177474 0.000165581"/>
                        <joint name="shoulder_right_3" pos="0 0 0" axis="0 0 1"/>
                        <geom pos="-0.00553045 0 -0.0571401" quat="0.706434 -0.706434 -0.0308436 -0.0308436" type="mesh" class="fluid-ellipsoid-model" contype="0" conaffinity="0" group="1" density="0" rgba="0.901961 0.901961 0.901961 1" mesh="front_flipper_straight"/>
                      <geom pos="-0.00553045 0 -0.0571401" quat="0.706434 -0.706434 -0.0308436 -0.0308436" type="mesh" rgba="0.901961 0.901961 0.901961 1" mesh="front_flipper_straight"/>
                    </body> -->
                    <body name="rigid_flipper_1" pos="-0.031 -0.0265 -0.026" quat="0.707107 -0.707107 0 0">
                      <inertial pos="0.00248568 8.33267e-05 -0.0355245" quat="0.675174 -0.210821 -0.212128 0.674312" mass="0.06156" diaginertia="2.83892e-05 2.13567e-05 1.0366e-05"/>
                      <joint name="shoulder_right_3" pos="0 0 0" axis="0 0 1"/>
                      <geom pos="-0.00553045 0 -0.0571401" quat="0.706434 -0.706434 -0.0308436 -0.0308436" type="mesh" class="fluid-ellipsoid-model" contype="0" conaffinity="0" group="1" density="0" rgba="0.901961 0.901961 0.901961 1" mesh="rigid_flipper_1"/>
                      <body name="rigid_flipper_2" pos="0.00196386 0.000100001 -0.0556748" quat="0 0.830782 0 0.556597">
                        <inertial pos="-0.0362247 -3.39236e-07 0.0121585" quat="0.674214 -0.213175 -0.213157 0.674208" mass="0.18" diaginertia="0.000164064 0.000115052 6.18787e-05"/>
                        <joint name="flipper_bend_R1" pos="0 0 0" axis="0 0 1" stiffness="1"/>
                        <joint name="flipper_twist_R1" pos="0 0 0" axis="-1 0 0" stiffness="0.1"/>
                        <geom pos="-0.004206 9.99841e-05 -0.00637349" quat="0.60406 0.60406 -0.367575 0.367575" type="mesh" class="fluid-ellipsoid-model" contype="0" conaffinity="0" group="1" density="0" rgba="0.901961 0.901961 0.901961 1" mesh="rigid_flipper_2"/>
                        <body name="rigid_flipper_4" pos="-0.071 1.92879e-07 0.0240195">
                          <inertial pos="-0.0307916 -4.64917e-07 0.00916138" quat="0.669186 -0.22841 -0.228413 0.669214" mass="0.139455" diaginertia="0.000108842 7.30735e-05 4.37205e-05"/>
                          <joint name="flipper_bend_R2" pos="0 0 0" axis="0 0 1" stiffness="1"/>
                          <joint name="flipper_twist_R2" pos="0 0 0" axis="-1 0 0" stiffness="0.1"/>
                          <geom pos="0.066794 9.99554e-05 -0.0303912" quat="0.60406 0.60406 -0.367575 0.367575" type="mesh" class="fluid-ellipsoid-model" contype="0" conaffinity="0" group="1" density="0" rgba="0.901961 0.901961 0.901961 1" mesh="rigid_flipper_4"/>
                          <body name="rigid_flipper_3" pos="-0.067 -6.2183e-08 0.0185906">
                            <inertial pos="-0.028812 3.4909e-08 0.00475549" quat="0.447453 0.547528 0.547527 0.447452" mass="0.066825" diaginertia="3.97925e-05 2.9138e-05 1.26273e-05"/>
                            <joint name="flipper_bend_R3" pos="0 0 0" axis="0 0 1" stiffness="1"/>
                            <joint name="flipper_twist_R3" pos="0 0 0" axis="-1 0 0" stiffness="0.1"/>
                            <geom pos="0.133794 0.000100018 -0.0489813" quat="0.60406 0.60406 -0.367575 0.367575" type="mesh" class="fluid-ellipsoid-model" contype="0" conaffinity="0" group="1" density="0" rgba="0.901961 0.901961 0.901961 1" mesh="rigid_flipper_3"/>
                          </body>
                        </body>
                      </body>
                    </body>
                </body>
            </body>
            <site name="arm_left_base" pos="0.0 -0.0150704 0.0" />
            <body name="front_left_link_1" pos="0.118895 0.0129566 -0.0103195" quat="0.707107 0.707107 0 0">
                <inertial pos="0.053506 -0.00012799 0.0116908" quat="0.701658 -0.0987588 -0.0898396 0.699894"
                          mass="0.237653" diaginertia="0.000125729 0.00012228 8.62057e-05"/>
                <joint name="shoulder_left_1" pos="0 0 0" axis="0 0 1"/>
                <geom pos="0.058 0 -0.0045" quat="0 0 -0.707107 0.707107" type="mesh" contype="0" conaffinity="0"
                      group="1" density="0" rgba="0.615686 0.811765 0.929412 1" mesh="xw540.n105.i101.stp"/>
                <geom pos="0.058 0 -0.0045" quat="0 0 -0.707107 0.707107" type="mesh"
                      rgba="0.615686 0.811765 0.929412 1" mesh="xw540.n105.i101.stp"/>
                <geom pos="0.032 0 0.011" quat="0.5 0.5 0.5 -0.5" type="mesh" contype="0" conaffinity="0" group="1"
                      density="0" rgba="0.796078 0.823529 0.937255 1" mesh="fr13-s106k"/>
                <geom pos="0.032 0 0.011" quat="0.5 0.5 0.5 -0.5" type="mesh" rgba="0.796078 0.823529 0.937255 1"
                      mesh="fr13-s106k"/>
                <geom pos="0.03 0 0.0265" quat="0.5 0.5 0.5 -0.5" type="mesh" contype="0" conaffinity="0" group="1"
                      density="0" rgba="0.796078 0.823529 0.937255 1" mesh="fr13-h105k"/>
                <!--<geom pos="0.03 0 0.0265" quat="0.5 0.5 0.5 -0.5" type="mesh" rgba="0.796078 0.823529 0.937255 1"
                      mesh="fr13-h105k"/>-->
                <body name="front_left_link_2" pos="0.058 -0.0265 -0.0045" quat="0.5 -0.5 0.5 0.5">
                    <inertial pos="0.0161017 -0.000139957 -0.0242536" quat="0.00460319 0.709168 -0.00751842 0.704984"
                              mass="0.217333" diaginertia="0.000103428 9.13443e-05 6.49095e-05"/>
                    <joint name="shoulder_left_2" pos="0 0 0" axis="0 0 1"/>
                    <geom pos="0.031 0 -0.026" quat="0.5 0.5 0.5 -0.5" type="mesh" contype="0" conaffinity="0" group="1"
                          density="0" rgba="0.615686 0.811765 0.929412 1" mesh="xw540.n105.i101.stp"/>
                    <geom pos="0.031 0 -0.026" quat="0.5 0.5 0.5 -0.5" type="mesh" rgba="0.615686 0.811765 0.929412 1"
                          mesh="xw540.n105.i101.stp"/>
                    <geom pos="0.0155 0 0" quat="0.707107 -0.707107 0 0" type="mesh" contype="0" conaffinity="0"
                          group="1" density="0" rgba="0.796078 0.823529 0.937255 1" mesh="fr13-s106k"/>
                    <geom pos="0.0155 0 0" quat="0.707107 -0.707107 0 0" type="mesh" rgba="0.796078 0.823529 0.937255 1"
                          mesh="fr13-s106k"/>
                    <!-- <body name="front_flipper_left" pos="0.031 -0.0265 -0.026" quat="0 0 0.707107 0.707107">
                        <inertial pos="-0.00442517 9.82085e-05 -0.127518" quat="0.706603 0.0265123 0.026473 0.706618" mass="0.45" diaginertia="0.00191412 0.00177474 0.000165581"/>
                        <joint name="shoulder_left_3" pos="0 0 0" axis="0 0 1"/>
                        <geom pos="-0.00553045 0 -0.0571401" quat="0.706434 -0.706434 -0.0308436 -0.0308436" type="mesh" class="fluid-ellipsoid-model" contype="0" conaffinity="0" group="1" density="0" rgba="0.901961 0.901961 0.901961 1" mesh="front_flipper_straight"/>
                        <geom pos="-0.00553045 0 -0.0571401" quat="0.706434 -0.706434 -0.0308436 -0.0308436" type="mesh" rgba="0.901961 0.901961 0.901961 1" mesh="front_flipper_straight"/>
                    </body> -->
                    <body name="rigid_flipper_1_2" pos="0.031 -0.0265 -0.026" quat="0 0 -0.707107 -0.707107">
                      <inertial pos="0.00248568 8.33267e-05 -0.0355245" quat="0.675174 -0.210821 -0.212128 0.674312" mass="0.06156" diaginertia="2.83892e-05 2.13567e-05 1.0366e-05"/>
                      <joint name="shoulder_left_3" pos="0 0 0" axis="0 0 1"/>
                      <geom pos="-0.00553045 0 -0.0571401" quat="0.706434 -0.706434 -0.0308436 -0.0308436" type="mesh" class="fluid-ellipsoid-model" contype="0" conaffinity="0" group="1" density="0" rgba="0.901961 0.901961 0.901961 1" mesh="rigid_flipper_1"/>
                      <body name="rigid_flipper_2_2" pos="0.00196386 0.000100001 -0.0556748" quat="0 -0.830782 0 -0.556597">
                        <inertial pos="-0.0362247 -3.39236e-07 0.0121585" quat="0.674214 -0.213175 -0.213157 0.674208" mass="0.18" diaginertia="0.000164064 0.000115052 6.18787e-05"/>
                        <joint name="flipper_bend_L1" pos="0 0 0" axis="0 0 1" stiffness="1"/>
                        <joint name="flipper_twist_L1" pos="0 0 0" axis="-1 0 0" stiffness="0.1"/>
                        <geom pos="-0.004206 9.99841e-05 -0.00637349" quat="0.60406 0.60406 -0.367575 0.367575" type="mesh" class="fluid-ellipsoid-model" contype="0" conaffinity="0" group="1" density="0" rgba="0.901961 0.901961 0.901961 1" mesh="rigid_flipper_2"/>
                        <body name="rigid_flipper_4_2" pos="-0.071 1.92879e-07 0.0240195" quat="1 0 0 0">
                          <inertial pos="-0.0307916 -4.64917e-07 0.00916138" quat="0.669186 -0.22841 -0.228413 0.669214" mass="0.139455" diaginertia="0.000108842 7.30735e-05 4.37205e-05"/>
                          <joint name="flipper_bend_L2" pos="0 0 0" axis="0 0 1" stiffness="1"/>
                          <joint name="flipper_twist_L2" pos="0 0 0" axis="-1 0 0" stiffness="0.1"/>
                          <geom pos="0.066794 9.99554e-05 -0.0303912" quat="0.60406 0.60406 -0.367575 0.367575" type="mesh" class="fluid-ellipsoid-model" contype="0" conaffinity="0" group="1" density="0" rgba="0.901961 0.901961 0.901961 1" mesh="rigid_flipper_4"/>
                          <body name="rigid_flipper_3_2" pos="-0.067 -6.2183e-08 0.0185906">
                            <inertial pos="-0.028812 3.4909e-08 0.00475549" quat="0.447453 0.547528 0.547527 0.447452" mass="0.066825" diaginertia="3.97925e-05 2.9138e-05 1.26273e-05"/>
                            <joint name="flipper_bend_L3" pos="0 0 0" axis="0 0 1" stiffness="1"/>
                            <joint name="flipper_twist_L3" pos="0 0 0" axis="-1 0 0" stiffness="0.1"/>
                            <geom pos="0.133794 0.000100018 -0.0489813" quat="0.60406 0.60406 -0.367575 0.367575" type="mesh" class="fluid-ellipsoid-model" contype="0" conaffinity="0" group="1" density="0" rgba="0.901961 0.901961 0.901961 1" mesh="rigid_flipper_3"/>
                          </body>
                        </body>
                      </body>
                    </body>
                </body>
            </body>
            <site name="leg_right_base" pos="0.0 0.294678 0.0" />
            <body name="rear_right_link_1" pos="-0.0998948 0.294678 0.0161805">
                <inertial pos="-0.00174642 0.0148983 -0.02654" quat="0.701015 0.713137 0.000634249 0.00354948"
                          mass="0.217333" diaginertia="0.000103428 9.13443e-05 6.49095e-05"/>
                <joint name="hip_right_1" pos="0 0 0" axis="0 0 1"/>
                <geom pos="0 0 -0.0264" quat="0 1 0 0" type="mesh" contype="0" conaffinity="0" group="1" density="0"
                      rgba="0.615686 0.811765 0.929412 1" mesh="xw540.n105.i101.stp"/>
                <!--<geom pos="0 0 -0.0264" quat="0 1 0 0" type="mesh" rgba="0.615686 0.811765 0.929412 1"
                      mesh="xw540.n105.i101.stp"/>-->
                <geom pos="-0.026 0.0155 -0.0264" quat="0 -0.707107 -0.707107 0" type="mesh" contype="0" conaffinity="0"
                      group="1" density="0" rgba="0.796078 0.823529 0.937255 1" mesh="fr13-s106k"/>
                <geom pos="-0.026 0.0155 -0.0264" quat="0 -0.707107 -0.707107 0" type="mesh"
                      rgba="0.796078 0.823529 0.937255 1" mesh="fr13-s106k"/>
                <body name="rear_right_link_2" pos="-0.026 0 -0.0264" quat="0 -0.707107 0 -0.707107">
                    <inertial pos="-1.45431e-07 -0.0585289 -0.0221094" quat="0.737336 0.675526 1.08265e-05 -1.55402e-05"
                              mass="0.378725" diaginertia="0.0011479 0.00108244 0.000118497"/>
                    <joint name="hip_right_2" pos="0 0 0" axis="0 0 1"/>
                    <geom pos="0 0 -0.0265" type="mesh" contype="0" conaffinity="0" group="1" density="0"
                          rgba="0.615686 0.811765 0.929412 1" mesh="xw540.n105.i101.stp"/>
                    <geom pos="0 0 -0.0265" type="mesh" rgba="0.615686 0.811765 0.929412 1" mesh="xw540.n105.i101.stp"/>
                    <geom pos="0 -0.051 -0.0265" type="mesh" contype="0" conaffinity="0" group="1" density="0"
                          rgba="0.796078 0.823529 0.937255 1" mesh="fr13-s105k"/>
                    <geom pos="0 -0.051 -0.0265" type="mesh" rgba="0.796078 0.823529 0.937255 1" mesh="fr13-s105k"/>
                    <geom pos="0 -0.0760786 -0.0299184" quat="0.663497 0.244483 -0.244483 0.663497" type="mesh"
                          class="fluid-ellipsoid-model" contype="0" conaffinity="0" group="1" density="0"
                          rgba="0.768627 0.886275 0.952941 1" mesh="rear_flipper"/>
                    <geom pos="0 -0.0760786 -0.0299184" quat="0.663497 0.244483 -0.244483 0.663497" type="mesh"
                          rgba="0.768627 0.886275 0.952941 1" mesh="rear_flipper"/>
                </body>
            </body>
            <site name="leg_left_base" pos="0.0 0.294678 0.0" />
            <body name="rear_left_link_1" pos="0.0998948 0.294805 0.0161805">
                <inertial pos="0.00174642 0.0148983 -0.02654" quat="0.701061 0.713093 -0.000633581 -0.00355021"
                          mass="0.217333" diaginertia="0.000103428 9.13442e-05 6.49096e-05"/>
                <joint name="hip_left_1" pos="0 0 0" axis="0 0 1"/>
                <geom pos="0.026 0.0155 -0.0264" quat="0.707107 0 0 0.707107" type="mesh" contype="0" conaffinity="0"
                      group="1" density="0" rgba="0.796078 0.823529 0.937255 1" mesh="fr13-s106k"/>
                <geom pos="0.026 0.0155 -0.0264" quat="0.707107 0 0 0.707107" type="mesh"
                      rgba="0.796078 0.823529 0.937255 1" mesh="fr13-s106k"/>
                <geom pos="0 0 -0.0264" quat="0 1 0 0" type="mesh" contype="0" conaffinity="0" group="1" density="0"
                      rgba="0.615686 0.811765 0.929412 1" mesh="xw540.n105.i101.stp"/>
                <!--<geom pos="0 0 -0.0264" quat="0 1 0 0" type="mesh" rgba="0.615686 0.811765 0.929412 1"
                      mesh="xw540.n105.i101.stp"/>-->
                <body name="rear_left_link_2" pos="0.026 0 -0.0264" quat="0 -0.707107 0 0.707107">
                    <inertial pos="-1.45431e-07 -0.0585289 -0.0221094" quat="0.737336 0.675526 1.08265e-05 -1.55402e-05"
                              mass="0.378725" diaginertia="0.0011479 0.00108244 0.000118497"/>
                    <joint name="hip_left_2" pos="0 0 0" axis="0 0 1"/>
                    <geom pos="0 -0.051 -0.0265" type="mesh" contype="0" conaffinity="0" group="1" density="0"
                          rgba="0.796078 0.823529 0.937255 1" mesh="fr13-s105k"/>
                    <geom pos="0 -0.051 -0.0265" type="mesh" rgba="0.796078 0.823529 0.937255 1" mesh="fr13-s105k"/>
                    <geom pos="0 0 -0.0265" type="mesh" contype="0" conaffinity="0" group="1" density="0"
                          rgba="0.615686 0.811765 0.929412 1" mesh="xw540.n105.i101.stp"/>
                    <geom pos="0 0 -0.0265" type="mesh" rgba="0.615686 0.811765 0.929412 1" mesh="xw540.n105.i101.stp"/>
                    <geom pos="0 -0.0760786 -0.0299184" quat="0.663497 0.244483 -0.244483 0.663497" type="mesh"
                          class="fluid-ellipsoid-model" contype="0" conaffinity="0" group="1" density="0"
                          rgba="0.768627 0.886275 0.952941 1" mesh="rear_flipper"/>
                    <geom pos="0 -0.0760786 -0.0299184" quat="0.663497 0.244483 -0.244483 0.663497" type="mesh"
                          rgba="0.768627 0.886275 0.952941 1" mesh="rear_flipper"/>
                </body>
            </body>
        </body>
    </worldbody>
</mujoco>
