<mujoco model="turtle_body">
    <compiler angle="radian" meshdir="meshes/" autolimits="true" />
    <option integrator="implicit" timestep="0.005" gravity="0 0 0" density="1000" viscosity="0.0009" cone="elliptic" />
    <asset>
      <mesh name="fr13-h105k" file="fr13-h105k.stl"/>
      <mesh name="fr13-s105k" file="fr13-s105k.stl"/>
      <mesh name="wte3-m-locking-flange-seal-r1-rp" file="wte3-m-locking-flange-seal-r1-rp.stl"/>
      <mesh name="part_7" file="part_7.stl"/>
      <mesh name="part_8" file="part_8.stl"/>
      <mesh name="xw540.n105.i101.stp" file="xw540.n105.i101.stp.stl"/>
      <mesh name="tube" file="tube.stl"/>
      <mesh name="part_5" file="part_5.stl"/>
      <mesh name="part_2" file="part_2.stl"/>
      <mesh name="part_4" file="part_4.stl"/>
      <mesh name="part_6" file="part_6.stl"/>
      <mesh name="part_3" file="part_3.stl"/>
      <mesh name="shoulder_adapter_l" file="shoulder_adapter_l.stl"/>
      <mesh name="shoulder_adapter_r" file="shoulder_adapter_r.stl"/>
      <mesh name="enclosure_plate" file="enclosure_plate.stl"/>
      <mesh name="head_bottom" file="head_bottom.stl"/>
      <mesh name="head_top" file="head_top.stl"/>
      <mesh name="explorehd_2.0_public.step-1-solid1" file="explorehd_2.0_public.step-1-solid1.stl"/>
      <mesh name="92467a452_18-8_stainless_steel_extra-wide_truss_head_phillips_screws.step-2-solid1" file="92467a452_18-8_stainless_steel_extra-wide_truss_head_phillips_screws.step-2-solid1.stl"/>
      <mesh name="explorehd_2.0_case_public.step-1_standoff_and_washer_v4_(1).step-1-solid1" file="explorehd_2.0_case_public.step-1_standoff_and_washer_v4_(1).step-1-solid1.stl"/>
      <mesh name="fr13-s106k" file="fr13-s106k.stl"/>
      <mesh name="rigid_flipper_4" file="rigid_flipper_4.stl"/>
      <mesh name="rear_flipper" file="rear_flipper.stl"/>
    </asset>
    <default>
        <default class="fluid-ellipsoid-model">
            <geom fluidshape="ellipsoid"/>
        </default>
    </default>
    <worldbody>
      <body name="base" quat="0.0 0.0 0.0 1.0">
        <inertial pos="4.14357e-07 0.0844756 0.00697314" quat="0.500725 0.499269 -0.499294 0.500709" mass="2.9553"
                      diaginertia="0.0661585 0.0610428 0.0094174"/>
        <joint name="world_frame_to_base" type="free" axis="0.0 -1.0 0.0" />
        <site name="base_cog" pos="4.14357e-07 0.0844756 0.00697314"/>
        <geom pos="-0.0698948 0.294678 0.0309494" quat="0.5 0.5 0.5 -0.5" type="mesh" rgba="0.796078 0.823529 0.937255 1" mesh="fr13-h105k"/>
        <geom pos="-0.0678948 -0.0134434 0.0309494" quat="0.5 0.5 -0.5 0.5" type="mesh" rgba="0.796078 0.823529 0.937255 1" mesh="fr13-s105k"/>
        <geom pos="0 0.0172412 0.010315" quat="0 0 0.707107 -0.707107" type="mesh" rgba="0.768627 0.886275 0.952941 1" mesh="wte3-m-locking-flange-seal-r1-rp"/>
        <geom pos="-0.00427997 0.155043 -0.0147573" quat="-0.0069054 -0.707073 0.706512 -0.0290079" type="mesh" rgba="0.25098 0.25098 0.25098 1" mesh="part_7"/>
        <geom pos="-0.00427997 0.155043 -0.0147573" quat="-0.0069054 -0.707073 0.706512 -0.0290079" type="mesh" rgba="0.25098 0.25098 0.25098 1" mesh="part_8"/>
        <geom pos="-0.118895 -0.0134434 0.0309494" quat="0.5 0.5 -0.5 0.5" type="mesh" rgba="0.615686 0.811765 0.929412 1" mesh="xw540.n105.i101.stp"/>
        <geom pos="0.118895 -0.0134434 0.0309494" quat="0.5 0.5 0.5 -0.5" type="mesh" rgba="0.615686 0.811765 0.929412 1" mesh="xw540.n105.i101.stp"/>
        <geom pos="0 0.140241 0.010315" quat="0 0 0.707107 -0.707107" type="mesh" rgba="1 1 1 1" mesh="tube"/>
        <geom pos="0.0698948 0.294678 0.0309494" quat="0.5 -0.5 0.5 0.5" type="mesh" rgba="0.796078 0.823529 0.937255 1" mesh="fr13-h105k"/>
        <geom pos="-0.00427997 0.155043 -0.0147573" quat="-0.0069054 -0.707073 0.706512 -0.0290079" type="mesh" rgba="0.25098 0.25098 0.25098 1" mesh="part_5"/>
        <geom pos="0 0.263241 0.010315" quat="0.707107 -0.707107 0 0" type="mesh" rgba="0.768627 0.886275 0.952941 1" mesh="wte3-m-locking-flange-seal-r1-rp"/>
        <geom pos="-0.00427997 0.155043 -0.0147573" quat="-0.0069054 -0.707073 0.706512 -0.0290079" type="mesh" rgba="0.25098 0.25098 0.25098 1" mesh="part_2"/>
        <geom pos="-0.00427997 0.155043 -0.0147573" quat="-0.0069054 -0.707073 0.706512 -0.0290079" type="mesh" rgba="0.25098 0.25098 0.25098 1" mesh="part_4"/>
        <geom pos="0.0678948 -0.0134434 0.0309494" quat="0.5 0.5 0.5 -0.5" type="mesh" rgba="0.796078 0.823529 0.937255 1" mesh="fr13-s105k"/>
        <geom pos="-0.00427997 0.155043 -0.0147573" quat="-0.0069054 -0.707073 0.706512 -0.0290079" type="mesh" rgba="0.25098 0.25098 0.25098 1" mesh="part_6"/>
        <geom pos="-0.00427997 0.155043 -0.0147573" quat="-0.0069054 -0.707073 0.706512 -0.0290079" type="mesh" rgba="0.25098 0.25098 0.25098 1" mesh="part_3"/>
        <geom pos="-0.0479333 -0.0179434 0.0590863" quat="0.707107 -0.707107 0 0" type="mesh" rgba="0.25098 0.25098 0.25098 1" mesh="shoulder_adapter_l"/>
        <geom pos="-0.0479333 -0.0179434 0.0590863" quat="0.707107 -0.707107 0 0" type="mesh" rgba="0.25098 0.25098 0.25098 1" mesh="shoulder_adapter_r"/>
        <geom pos="-0.0479333 -0.0180069 0.0590863" quat="0.707107 -0.707107 0 0" type="mesh" rgba="1 1 1 1" mesh="enclosure_plate"/>
        <geom pos="-1.024e-12 -0.0406034 0.010315" quat="0 0 0.707107 -0.707107" type="mesh" rgba="0.25098 0.25098 0.25098 1" mesh="head_bottom"/>
        <geom pos="-1.02398e-12 -0.0406034 0.010315" quat="0 0 0.707107 -0.707107" type="mesh" rgba="0.25098 0.25098 0.25098 1" mesh="head_top"/>
        <geom pos="0.0479333 0.299178 0.0590863" quat="0 0 0.707107 -0.707107" type="mesh" rgba="0.25098 0.25098 0.25098 1" mesh="shoulder_adapter_l"/>
        <geom pos="0.0479333 0.299178 0.0590863" quat="0 0 0.707107 -0.707107" type="mesh" rgba="0.25098 0.25098 0.25098 1" mesh="shoulder_adapter_r"/>
        <geom pos="0.0479333 0.299241 0.0590863" quat="0 0 0.707107 -0.707107" type="mesh" rgba="1 1 1 1" mesh="enclosure_plate"/>
        <geom pos="0.0267103 -0.14548 -0.015073" quat="0.560986 0.430459 0.560986 -0.430459" type="mesh" rgba="0.796078 0.823529 0.937255 1" mesh="explorehd_2.0_public.step-1-solid1"/>
        <geom pos="0.0208125 -0.146256 -0.014734" quat="0.5 0.5 -0.5 0.5" type="mesh" rgba="0.796078 0.823529 0.937255 1" mesh="92467a452_18-8_stainless_steel_extra-wide_truss_head_phillips_screws.step-2-solid1"/>
        <geom pos="0.0267103 -0.14548 -0.015073" quat="0.560986 0.430459 0.560986 -0.430459" type="mesh" rgba="0.796078 0.823529 0.937255 1" mesh="explorehd_2.0_case_public.step-1_standoff_and_washer_v4_(1).step-1-solid1"/>
        <geom pos="-0.0209147 -0.147033 -0.015073" quat="0.430459 0.560986 0.430459 -0.560986" type="mesh" rgba="0.796078 0.823529 0.937255 1" mesh="explorehd_2.0_public.step-1-solid1"/>
        <geom pos="-0.0268125 -0.146256 -0.014734" quat="0.5 0.5 -0.5 0.5" type="mesh" rgba="0.796078 0.823529 0.937255 1" mesh="92467a452_18-8_stainless_steel_extra-wide_truss_head_phillips_screws.step-2-solid1"/>
        <geom pos="-0.0209147 -0.147033 -0.015073" quat="0.430459 0.560986 0.430459 -0.560986" type="mesh" rgba="0.796078 0.823529 0.937255 1" mesh="explorehd_2.0_case_public.step-1_standoff_and_washer_v4_(1).step-1-solid1"/>
        <body name="right_front_link_1" pos="0.118895 -0.0399434 0.0309494" quat="0.707107 -0.707107 0 0">
          <inertial pos="0.053506 -0.00012799 0.0413092" quat="0.701572 0.0987989 0.0897983 0.69998" mass="0.237653" diaginertia="0.000125729 0.00012228 8.62056e-05"/>
          <joint name="shoulderR1" pos="0 0 0" axis="0 0 1" actuatorfrcrange="-1 1"/>
          <geom pos="0.032 0 0.042" quat="0.5 0.5 0.5 -0.5" type="mesh" rgba="0.796078 0.823529 0.937255 1" mesh="fr13-s106k"/>
          <geom pos="0.03 0 0.0265" quat="0.5 -0.5 -0.5 -0.5" type="mesh" rgba="0.796078 0.823529 0.937255 1" mesh="fr13-h105k"/>
          <geom pos="0.058 0 0.0575" quat="0.707107 0.707107 0 0" type="mesh" rgba="0.615686 0.811765 0.929412 1" mesh="xw540.n105.i101.stp"/>
          <body name="right_front_link_2" pos="0.058 -0.0265 0.0575" quat="0.5 -0.5 0.5 0.5">
            <inertial pos="-0.0161017 -0.000139957 -0.0242536" quat="-0.00747436 0.704985 0.00455773 0.709168" mass="0.217333" diaginertia="0.000103428 9.13442e-05 6.49096e-05"/>
            <joint name="shoulderR2" pos="0 0 0" axis="0 0 1" actuatorfrcrange="-1 1"/>
            <geom pos="-0.0155 0 0" quat="0.707107 -0.707107 0 0" type="mesh" rgba="0.796078 0.823529 0.937255 1" mesh="fr13-s106k"/>
            <geom pos="-0.031 0 -0.026" quat="0.5 0.5 -0.5 0.5" type="mesh" rgba="0.615686 0.811765 0.929412 1" mesh="xw540.n105.i101.stp"/>
            <body name="rigid_flipper_4" pos="-0.031 -0.0265 -0.026" quat="0.707107 -0.707107 0 0">
              <inertial pos="-0.00440635 9.77561e-05 -0.127023" quat="0.706606 0.0263024 0.0262537 0.706631" mass="0.139455" diaginertia="0.00059915 0.000556112 5.1181e-05"/>
              <joint name="shoulderR3" pos="0 0 0" axis="0 0 1" actuatorfrcrange="-1 1"/>
              <geom pos="-0.00553045 0 -0.0571401" quat="0.706434 -0.706434 -0.0308436 -0.0308436" type="mesh" rgba="0.901961 0.901961 0.901961 1" mesh="rigid_flipper_4"/>
            </body>
          </body>
        </body>
        <body name="left_front_link_1" pos="-0.118895 0.0129566 0.0309494" quat="0 0 0.707107 -0.707107">
          <inertial pos="0.053506 -0.00012799 0.0116908" quat="0.701658 -0.0987588 -0.0898396 0.699894" mass="0.237653" diaginertia="0.000125729 0.00012228 8.62057e-05"/>
          <joint name="shoulderL1" pos="0 0 0" axis="0 0 1" actuatorfrcrange="-1 1"/>
          <geom pos="0.058 0 -0.0045" quat="0 0 -0.707107 0.707107" type="mesh" rgba="0.615686 0.811765 0.929412 1" mesh="xw540.n105.i101.stp"/>
          <geom pos="0.032 0 0.011" quat="0.5 0.5 0.5 -0.5" type="mesh" rgba="0.796078 0.823529 0.937255 1" mesh="fr13-s106k"/>
          <geom pos="0.03 0 0.0265" quat="0.5 0.5 0.5 -0.5" type="mesh" rgba="0.796078 0.823529 0.937255 1" mesh="fr13-h105k"/>
          <body name="left_front_link_2" pos="0.058 -0.0265 -0.0045" quat="0.5 -0.5 0.5 0.5">
            <inertial pos="0.0161017 -0.000139957 -0.0242536" quat="0.00460319 0.709168 -0.00751842 0.704984" mass="0.217333" diaginertia="0.000103428 9.13443e-05 6.49095e-05"/>
            <joint name="shoulderL2" pos="0 0 0" axis="0 0 1" actuatorfrcrange="-1 1"/>
            <geom pos="0.031 0 -0.026" quat="0.5 0.5 0.5 -0.5" type="mesh" rgba="0.615686 0.811765 0.929412 1" mesh="xw540.n105.i101.stp"/>
            <geom pos="0.0155 0 0" quat="0.707107 -0.707107 0 0" type="mesh" rgba="0.796078 0.823529 0.937255 1" mesh="fr13-s106k"/>
            <body name="rigid_flipper_4_2" pos="0.031 -0.0265 -0.026" quat="0 0 -0.707107 -0.707107">
              <inertial pos="-0.00440635 9.77561e-05 -0.127023" quat="0.706606 0.0263024 0.0262537 0.706631" mass="0.139455" diaginertia="0.00059915 0.000556112 5.1181e-05"/>
              <joint name="shoulderL3" pos="0 0 0" axis="0 0 1" actuatorfrcrange="-1 1"/>
              <geom pos="-0.00553045 0 -0.0571401" quat="0.706434 -0.706434 -0.0308436 -0.0308436" type="mesh" rgba="0.901961 0.901961 0.901961 1" mesh="rigid_flipper_4"/>
            </body>
          </body>
        </body>
        <body name="right_rear_link_1" pos="0.0998948 0.294678 0.00444941" quat="0 0 -1 0">
          <inertial pos="-0.00174642 0.0148983 -0.02654" quat="0.701015 0.713137 0.000634249 0.00354948" mass="0.217333" diaginertia="0.000103428 9.13443e-05 6.49095e-05"/>
          <joint name="hipR1" pos="0 0 0" axis="0 0 1" actuatorfrcrange="-1 1"/>
          <geom pos="0 0 -0.0264" quat="0 -1 0 0" type="mesh" rgba="0.615686 0.811765 0.929412 1" mesh="xw540.n105.i101.stp"/>
          <geom pos="-0.026 0.0155 -0.0264" quat="0 -0.707107 -0.707107 0" type="mesh" rgba="0.796078 0.823529 0.937255 1" mesh="fr13-s106k"/>
          <body name="right_rear_link_2" pos="-0.026 0 -0.0264" quat="0 -0.707107 0 -0.707107">
            <inertial pos="-1.45431e-07 -0.0585289 -0.0221094" quat="0.737336 0.675526 1.08265e-05 -1.55402e-05" mass="0.378725" diaginertia="0.0011479 0.00108244 0.000118497"/>
            <joint name="hipR2" pos="0 0 0" axis="0 0 1" actuatorfrcrange="-1 1"/>
            <geom pos="0 0 -0.0265" quat="1 0 0 0" type="mesh" rgba="0.615686 0.811765 0.929412 1" mesh="xw540.n105.i101.stp"/>
            <geom pos="0 -0.0760786 -0.0299184" quat="0.663497 0.244483 -0.244483 0.663497" type="mesh" rgba="0.768627 0.886275 0.952941 1" mesh="rear_flipper"/>
            <geom pos="0 -0.051 -0.0265" quat="1 0 0 0" type="mesh" rgba="0.796078 0.823529 0.937255 1" mesh="fr13-s105k"/>
          </body>
        </body>
        <body name="left_rear_link_1" pos="-0.0998948 0.294678 0.00444941" quat="0 0 1 0">
          <inertial pos="0.00174642 0.0148983 -0.02654" quat="0.701061 0.713093 -0.000633581 -0.00355021" mass="0.217333" diaginertia="0.000103428 9.13442e-05 6.49096e-05"/>
          <joint name="hipL1" pos="0 0 0" axis="0 0 1" actuatorfrcrange="-1 1"/>
          <geom pos="0.026 0.0155 -0.0264" quat="0.707107 0 0 0.707107" type="mesh" rgba="0.796078 0.823529 0.937255 1" mesh="fr13-s106k"/>
          <geom pos="0 0 -0.0264" quat="0 1 0 0" type="mesh" rgba="0.615686 0.811765 0.929412 1" mesh="xw540.n105.i101.stp"/>
          <body name="left_rear_link_2" pos="0.026 0 -0.0264" quat="0 -0.707107 0 0.707107">
            <inertial pos="-1.45431e-07 -0.0585289 -0.0221094" quat="0.737336 0.675526 1.08265e-05 -1.55402e-05" mass="0.378725" diaginertia="0.0011479 0.00108244 0.000118497"/>
            <joint name="hipL2" pos="0 0 0" axis="0 0 1" actuatorfrcrange="-1 1"/>
            <geom pos="0 -0.051 -0.0265" quat="1 0 0 0" type="mesh" rgba="0.796078 0.823529 0.937255 1" mesh="fr13-s105k"/>
            <geom pos="0 0 -0.0265" quat="1 0 0 0" type="mesh" rgba="0.615686 0.811765 0.929412 1" mesh="xw540.n105.i101.stp"/>
            <geom pos="0 -0.0760786 -0.0299184" quat="0.663497 0.244483 -0.244483 0.663497" type="mesh" rgba="0.768627 0.886275 0.952941 1" mesh="rear_flipper"/>
          </body>
        </body>
      </body>
    </worldbody>
</mujoco>
